WARNING 2021-04-12 20:18:37,953 log 228 Not Found: /favicon.ico
WARNING 2021-04-12 20:18:37,954 basehttp 154 "GET /favicon.ico HTTP/1.1" 404 1973
ERROR 2021-04-13 03:25:16,252 exception 118 Internal Server Error: /home/header/
Traceback (most recent call last):
  File "C:\Users\12100\AppData\Local\Programs\Python\Python36\lib\site-packages\django\core\handlers\exception.py", line 35, in inner
    response = get_response(request)
  File "C:\Users\12100\AppData\Local\Programs\Python\Python36\lib\site-packages\django\core\handlers\base.py", line 128, in _get_response
    response = self.process_exception_by_middleware(e, request)
  File "C:\Users\12100\AppData\Local\Programs\Python\Python36\lib\site-packages\django\core\handlers\base.py", line 126, in _get_response
    response = wrapped_callback(request, *callback_args, **callback_kwargs)
  File "C:\Users\12100\AppData\Local\Programs\Python\Python36\lib\site-packages\django\views\decorators\csrf.py", line 54, in wrapped_view
    return view_func(*args, **kwargs)
  File "C:\Users\12100\AppData\Local\Programs\Python\Python36\lib\site-packages\django\views\generic\base.py", line 69, in view
    return self.dispatch(request, *args, **kwargs)
  File "C:\Users\12100\AppData\Local\Programs\Python\Python36\lib\site-packages\rest_framework\views.py", line 497, in dispatch
    response = self.handle_exception(exc)
  File "C:\Users\12100\AppData\Local\Programs\Python\Python36\lib\site-packages\rest_framework\views.py", line 457, in handle_exception
    self.raise_uncaught_exception(exc)
  File "C:\Users\12100\AppData\Local\Programs\Python\Python36\lib\site-packages\rest_framework\views.py", line 468, in raise_uncaught_exception
    raise exc
  File "C:\Users\12100\AppData\Local\Programs\Python\Python36\lib\site-packages\rest_framework\views.py", line 494, in dispatch
    response = handler(request, *args, **kwargs)
  File "C:\Users\12100\AppData\Local\Programs\Python\Python36\lib\site-packages\rest_framework\generics.py", line 199, in get
    return self.list(request, *args, **kwargs)
  File "C:\Users\12100\AppData\Local\Programs\Python\Python36\lib\site-packages\rest_framework\mixins.py", line 46, in list
    return Response(serializer.data)
  File "C:\Users\12100\AppData\Local\Programs\Python\Python36\lib\site-packages\rest_framework\serializers.py", line 757, in data
    ret = super().data
  File "C:\Users\12100\AppData\Local\Programs\Python\Python36\lib\site-packages\rest_framework\serializers.py", line 261, in data
    self._data = self.to_representation(self.instance)
  File "C:\Users\12100\AppData\Local\Programs\Python\Python36\lib\site-packages\rest_framework\serializers.py", line 675, in to_representation
    self.child.to_representation(item) for item in iterable
  File "C:\Users\12100\AppData\Local\Programs\Python\Python36\lib\site-packages\rest_framework\serializers.py", line 675, in <listcomp>
    self.child.to_representation(item) for item in iterable
  File "C:\Users\12100\AppData\Local\Programs\Python\Python36\lib\site-packages\rest_framework\serializers.py", line 511, in to_representation
    for field in fields:
  File "C:\Users\12100\AppData\Local\Programs\Python\Python36\lib\site-packages\rest_framework\serializers.py", line 372, in _readable_fields
    for field in self.fields.values():
  File "C:\Users\12100\AppData\Local\Programs\Python\Python36\lib\site-packages\django\utils\functional.py", line 36, in __get__
    res = instance.__dict__[self.name] = self.func(instance)
  File "C:\Users\12100\AppData\Local\Programs\Python\Python36\lib\site-packages\rest_framework\serializers.py", line 360, in fields
    for key, value in self.get_fields().items():
  File "C:\Users\12100\AppData\Local\Programs\Python\Python36\lib\site-packages\rest_framework\serializers.py", line 1047, in get_fields
    source, info, model, depth
  File "C:\Users\12100\AppData\Local\Programs\Python\Python36\lib\site-packages\rest_framework\serializers.py", line 1192, in build_field
    return self.build_unknown_field(field_name, model_class)
  File "C:\Users\12100\AppData\Local\Programs\Python\Python36\lib\site-packages\rest_framework\serializers.py", line 1309, in build_unknown_field
    (field_name, model_class.__name__)
django.core.exceptions.ImproperlyConfigured: Field name ` is_site` is not valid for model `Nav`.
ERROR 2021-04-13 03:25:16,727 basehttp 124 "GET /home/header/ HTTP/1.1" 500 21658
ERROR 2021-04-13 03:27:00,891 exception 118 Internal Server Error: /home/header/
Traceback (most recent call last):
  File "C:\Users\12100\AppData\Local\Programs\Python\Python36\lib\site-packages\django\core\handlers\exception.py", line 35, in inner
    response = get_response(request)
  File "C:\Users\12100\AppData\Local\Programs\Python\Python36\lib\site-packages\django\core\handlers\base.py", line 128, in _get_response
    response = self.process_exception_by_middleware(e, request)
  File "C:\Users\12100\AppData\Local\Programs\Python\Python36\lib\site-packages\django\core\handlers\base.py", line 126, in _get_response
    response = wrapped_callback(request, *callback_args, **callback_kwargs)
  File "C:\Users\12100\AppData\Local\Programs\Python\Python36\lib\site-packages\django\views\decorators\csrf.py", line 54, in wrapped_view
    return view_func(*args, **kwargs)
  File "C:\Users\12100\AppData\Local\Programs\Python\Python36\lib\site-packages\django\views\generic\base.py", line 69, in view
    return self.dispatch(request, *args, **kwargs)
  File "C:\Users\12100\AppData\Local\Programs\Python\Python36\lib\site-packages\rest_framework\views.py", line 497, in dispatch
    response = self.handle_exception(exc)
  File "C:\Users\12100\AppData\Local\Programs\Python\Python36\lib\site-packages\rest_framework\views.py", line 457, in handle_exception
    self.raise_uncaught_exception(exc)
  File "C:\Users\12100\AppData\Local\Programs\Python\Python36\lib\site-packages\rest_framework\views.py", line 468, in raise_uncaught_exception
    raise exc
  File "C:\Users\12100\AppData\Local\Programs\Python\Python36\lib\site-packages\rest_framework\views.py", line 494, in dispatch
    response = handler(request, *args, **kwargs)
  File "C:\Users\12100\AppData\Local\Programs\Python\Python36\lib\site-packages\rest_framework\generics.py", line 199, in get
    return self.list(request, *args, **kwargs)
  File "C:\Users\12100\AppData\Local\Programs\Python\Python36\lib\site-packages\rest_framework\mixins.py", line 46, in list
    return Response(serializer.data)
  File "C:\Users\12100\AppData\Local\Programs\Python\Python36\lib\site-packages\rest_framework\serializers.py", line 757, in data
    ret = super().data
  File "C:\Users\12100\AppData\Local\Programs\Python\Python36\lib\site-packages\rest_framework\serializers.py", line 261, in data
    self._data = self.to_representation(self.instance)
  File "C:\Users\12100\AppData\Local\Programs\Python\Python36\lib\site-packages\rest_framework\serializers.py", line 675, in to_representation
    self.child.to_representation(item) for item in iterable
  File "C:\Users\12100\AppData\Local\Programs\Python\Python36\lib\site-packages\rest_framework\serializers.py", line 675, in <listcomp>
    self.child.to_representation(item) for item in iterable
  File "C:\Users\12100\AppData\Local\Programs\Python\Python36\lib\site-packages\rest_framework\serializers.py", line 511, in to_representation
    for field in fields:
  File "C:\Users\12100\AppData\Local\Programs\Python\Python36\lib\site-packages\rest_framework\serializers.py", line 372, in _readable_fields
    for field in self.fields.values():
  File "C:\Users\12100\AppData\Local\Programs\Python\Python36\lib\site-packages\django\utils\functional.py", line 36, in __get__
    res = instance.__dict__[self.name] = self.func(instance)
  File "C:\Users\12100\AppData\Local\Programs\Python\Python36\lib\site-packages\rest_framework\serializers.py", line 360, in fields
    for key, value in self.get_fields().items():
  File "C:\Users\12100\AppData\Local\Programs\Python\Python36\lib\site-packages\rest_framework\serializers.py", line 1047, in get_fields
    source, info, model, depth
  File "C:\Users\12100\AppData\Local\Programs\Python\Python36\lib\site-packages\rest_framework\serializers.py", line 1192, in build_field
    return self.build_unknown_field(field_name, model_class)
  File "C:\Users\12100\AppData\Local\Programs\Python\Python36\lib\site-packages\rest_framework\serializers.py", line 1309, in build_unknown_field
    (field_name, model_class.__name__)
django.core.exceptions.ImproperlyConfigured: Field name ` is_site` is not valid for model `Nav`.
ERROR 2021-04-13 03:27:00,925 basehttp 124 "GET /home/header/ HTTP/1.1" 500 21658
ERROR 2021-04-13 03:27:10,977 exception 118 Internal Server Error: /home/header/
Traceback (most recent call last):
  File "C:\Users\12100\AppData\Local\Programs\Python\Python36\lib\site-packages\django\core\handlers\exception.py", line 35, in inner
    response = get_response(request)
  File "C:\Users\12100\AppData\Local\Programs\Python\Python36\lib\site-packages\django\core\handlers\base.py", line 128, in _get_response
    response = self.process_exception_by_middleware(e, request)
  File "C:\Users\12100\AppData\Local\Programs\Python\Python36\lib\site-packages\django\core\handlers\base.py", line 126, in _get_response
    response = wrapped_callback(request, *callback_args, **callback_kwargs)
  File "C:\Users\12100\AppData\Local\Programs\Python\Python36\lib\site-packages\django\views\decorators\csrf.py", line 54, in wrapped_view
    return view_func(*args, **kwargs)
  File "C:\Users\12100\AppData\Local\Programs\Python\Python36\lib\site-packages\django\views\generic\base.py", line 69, in view
    return self.dispatch(request, *args, **kwargs)
  File "C:\Users\12100\AppData\Local\Programs\Python\Python36\lib\site-packages\rest_framework\views.py", line 497, in dispatch
    response = self.handle_exception(exc)
  File "C:\Users\12100\AppData\Local\Programs\Python\Python36\lib\site-packages\rest_framework\views.py", line 457, in handle_exception
    self.raise_uncaught_exception(exc)
  File "C:\Users\12100\AppData\Local\Programs\Python\Python36\lib\site-packages\rest_framework\views.py", line 468, in raise_uncaught_exception
    raise exc
  File "C:\Users\12100\AppData\Local\Programs\Python\Python36\lib\site-packages\rest_framework\views.py", line 494, in dispatch
    response = handler(request, *args, **kwargs)
  File "C:\Users\12100\AppData\Local\Programs\Python\Python36\lib\site-packages\rest_framework\generics.py", line 199, in get
    return self.list(request, *args, **kwargs)
  File "C:\Users\12100\AppData\Local\Programs\Python\Python36\lib\site-packages\rest_framework\mixins.py", line 46, in list
    return Response(serializer.data)
  File "C:\Users\12100\AppData\Local\Programs\Python\Python36\lib\site-packages\rest_framework\serializers.py", line 757, in data
    ret = super().data
  File "C:\Users\12100\AppData\Local\Programs\Python\Python36\lib\site-packages\rest_framework\serializers.py", line 261, in data
    self._data = self.to_representation(self.instance)
  File "C:\Users\12100\AppData\Local\Programs\Python\Python36\lib\site-packages\rest_framework\serializers.py", line 675, in to_representation
    self.child.to_representation(item) for item in iterable
  File "C:\Users\12100\AppData\Local\Programs\Python\Python36\lib\site-packages\rest_framework\serializers.py", line 675, in <listcomp>
    self.child.to_representation(item) for item in iterable
  File "C:\Users\12100\AppData\Local\Programs\Python\Python36\lib\site-packages\rest_framework\serializers.py", line 511, in to_representation
    for field in fields:
  File "C:\Users\12100\AppData\Local\Programs\Python\Python36\lib\site-packages\rest_framework\serializers.py", line 372, in _readable_fields
    for field in self.fields.values():
  File "C:\Users\12100\AppData\Local\Programs\Python\Python36\lib\site-packages\django\utils\functional.py", line 36, in __get__
    res = instance.__dict__[self.name] = self.func(instance)
  File "C:\Users\12100\AppData\Local\Programs\Python\Python36\lib\site-packages\rest_framework\serializers.py", line 360, in fields
    for key, value in self.get_fields().items():
  File "C:\Users\12100\AppData\Local\Programs\Python\Python36\lib\site-packages\rest_framework\serializers.py", line 1047, in get_fields
    source, info, model, depth
  File "C:\Users\12100\AppData\Local\Programs\Python\Python36\lib\site-packages\rest_framework\serializers.py", line 1192, in build_field
    return self.build_unknown_field(field_name, model_class)
  File "C:\Users\12100\AppData\Local\Programs\Python\Python36\lib\site-packages\rest_framework\serializers.py", line 1309, in build_unknown_field
    (field_name, model_class.__name__)
django.core.exceptions.ImproperlyConfigured: Field name ` is_site` is not valid for model `Nav`.
ERROR 2021-04-13 03:27:11,020 basehttp 124 "GET /home/header/ HTTP/1.1" 500 21658
WARNING 2021-04-13 18:30:42,557 base 93 Not Found: /
WARNING 2021-04-13 18:30:42,557 basehttp 124 "GET / HTTP/1.1" 404 2151
WARNING 2021-04-13 18:30:43,180 base 93 Not Found: /favicon.ico
WARNING 2021-04-13 18:30:43,181 basehttp 124 "GET /favicon.ico HTTP/1.1" 404 2202
ERROR 2021-04-13 18:30:51,910 exception 118 Internal Server Error: /admin/
Traceback (most recent call last):
  File "C:\Users\Administrator\envs\demo\lib\site-packages\django\contrib\sessions\backends\base.py", line 191, in _get_session
    return self._session_cache
AttributeError: 'SessionStore' object has no attribute '_session_cache'

During handling of the above exception, another exception occurred:

Traceback (most recent call last):
  File "C:\Users\Administrator\envs\demo\lib\site-packages\django\db\backends\utils.py", line 85, in _execute
    return self.cursor.execute(sql, params)
  File "C:\Users\Administrator\envs\demo\lib\site-packages\django\db\backends\mysql\base.py", line 71, in execute
    return self.cursor.execute(query, args)
  File "C:\Users\Administrator\envs\demo\lib\site-packages\MySQLdb\cursors.py", line 206, in execute
    res = self._query(query)
  File "C:\Users\Administrator\envs\demo\lib\site-packages\MySQLdb\cursors.py", line 319, in _query
    db.query(q)
  File "C:\Users\Administrator\envs\demo\lib\site-packages\MySQLdb\connections.py", line 259, in query
    _mysql.connection.query(self, query)
MySQLdb._exceptions.ProgrammingError: (1146, "Table 'webpj.django_session' doesn't exist")

The above exception was the direct cause of the following exception:

Traceback (most recent call last):
  File "C:\Users\Administrator\envs\demo\lib\site-packages\django\core\handlers\exception.py", line 35, in inner
    response = get_response(request)
  File "C:\Users\Administrator\envs\demo\lib\site-packages\django\core\handlers\base.py", line 128, in _get_response
    response = self.process_exception_by_middleware(e, request)
  File "C:\Users\Administrator\envs\demo\lib\site-packages\django\core\handlers\base.py", line 126, in _get_response
    response = wrapped_callback(request, *callback_args, **callback_kwargs)
  File "C:\Users\Administrator\envs\demo\lib\site-packages\xadmin\sites.py", line 300, in wrapper
    return self.admin_view(view, cacheable)(*args, **kwargs)
  File "C:\Users\Administrator\envs\demo\lib\site-packages\django\views\decorators\cache.py", line 44, in _wrapped_view_func
    response = view_func(request, *args, **kwargs)
  File "C:\Users\Administrator\envs\demo\lib\site-packages\xadmin\sites.py", line 206, in inner
    if not self.has_permission(request) and getattr(view, 'need_site_permission', True):
  File "C:\Users\Administrator\envs\demo\lib\site-packages\xadmin\sites.py", line 161, in has_permission
    return request.user.is_active and request.user.is_staff
  File "C:\Users\Administrator\envs\demo\lib\site-packages\django\utils\functional.py", line 215, in inner
    self._setup()
  File "C:\Users\Administrator\envs\demo\lib\site-packages\django\utils\functional.py", line 349, in _setup
    self._wrapped = self._setupfunc()
  File "C:\Users\Administrator\envs\demo\lib\site-packages\django\contrib\auth\middleware.py", line 24, in <lambda>
    request.user = SimpleLazyObject(lambda: get_user(request))
  File "C:\Users\Administrator\envs\demo\lib\site-packages\django\contrib\auth\middleware.py", line 12, in get_user
    request._cached_user = auth.get_user(request)
  File "C:\Users\Administrator\envs\demo\lib\site-packages\django\contrib\auth\__init__.py", line 211, in get_user
    user_id = _get_user_session_key(request)
  File "C:\Users\Administrator\envs\demo\lib\site-packages\django\contrib\auth\__init__.py", line 61, in _get_user_session_key
    return get_user_model()._meta.pk.to_python(request.session[SESSION_KEY])
  File "C:\Users\Administrator\envs\demo\lib\site-packages\django\contrib\sessions\backends\base.py", line 55, in __getitem__
    return self._session[key]
  File "C:\Users\Administrator\envs\demo\lib\site-packages\django\contrib\sessions\backends\base.py", line 196, in _get_session
    self._session_cache = self.load()
  File "C:\Users\Administrator\envs\demo\lib\site-packages\django\contrib\sessions\backends\db.py", line 34, in load
    expire_date__gt=timezone.now()
  File "C:\Users\Administrator\envs\demo\lib\site-packages\django\db\models\manager.py", line 82, in manager_method
    return getattr(self.get_queryset(), name)(*args, **kwargs)
  File "C:\Users\Administrator\envs\demo\lib\site-packages\django\db\models\query.py", line 397, in get
    num = len(clone)
  File "C:\Users\Administrator\envs\demo\lib\site-packages\django\db\models\query.py", line 254, in __len__
    self._fetch_all()
  File "C:\Users\Administrator\envs\demo\lib\site-packages\django\db\models\query.py", line 1179, in _fetch_all
    self._result_cache = list(self._iterable_class(self))
  File "C:\Users\Administrator\envs\demo\lib\site-packages\django\db\models\query.py", line 53, in __iter__
    results = compiler.execute_sql(chunked_fetch=self.chunked_fetch, chunk_size=self.chunk_size)
  File "C:\Users\Administrator\envs\demo\lib\site-packages\django\db\models\sql\compiler.py", line 1068, in execute_sql
    cursor.execute(sql, params)
  File "C:\Users\Administrator\envs\demo\lib\site-packages\django\db\backends\utils.py", line 100, in execute
    return super().execute(sql, params)
  File "C:\Users\Administrator\envs\demo\lib\site-packages\django\db\backends\utils.py", line 68, in execute
    return self._execute_with_wrappers(sql, params, many=False, executor=self._execute)
  File "C:\Users\Administrator\envs\demo\lib\site-packages\django\db\backends\utils.py", line 77, in _execute_with_wrappers
    return executor(sql, params, many, context)
  File "C:\Users\Administrator\envs\demo\lib\site-packages\django\db\backends\utils.py", line 85, in _execute
    return self.cursor.execute(sql, params)
  File "C:\Users\Administrator\envs\demo\lib\site-packages\django\db\utils.py", line 89, in __exit__
    raise dj_exc_value.with_traceback(traceback) from exc_value
  File "C:\Users\Administrator\envs\demo\lib\site-packages\django\db\backends\utils.py", line 85, in _execute
    return self.cursor.execute(sql, params)
  File "C:\Users\Administrator\envs\demo\lib\site-packages\django\db\backends\mysql\base.py", line 71, in execute
    return self.cursor.execute(query, args)
  File "C:\Users\Administrator\envs\demo\lib\site-packages\MySQLdb\cursors.py", line 206, in execute
    res = self._query(query)
  File "C:\Users\Administrator\envs\demo\lib\site-packages\MySQLdb\cursors.py", line 319, in _query
    db.query(q)
  File "C:\Users\Administrator\envs\demo\lib\site-packages\MySQLdb\connections.py", line 259, in query
    _mysql.connection.query(self, query)
django.db.utils.ProgrammingError: (1146, "Table 'webpj.django_session' doesn't exist")
ERROR 2021-04-13 18:30:55,081 basehttp 124 "GET /admin/ HTTP/1.1" 500 217811
WARNING 2021-04-13 18:33:11,834 base 93 Not Found: /
WARNING 2021-04-13 18:33:11,835 basehttp 124 "GET / HTTP/1.1" 404 2151
ERROR 2021-04-13 18:33:45,582 basehttp 124 "GET /admin/ HTTP/1.1" 500 59
WARNING 2021-04-13 18:33:47,200 csrf 153 Forbidden (CSRF token missing or incorrect.): /admin/
WARNING 2021-04-13 18:33:47,204 basehttp 124 "POST /admin/ HTTP/1.1" 403 2508
WARNING 2021-04-13 18:34:11,301 csrf 153 Forbidden (CSRF token missing or incorrect.): /admin/
WARNING 2021-04-13 18:34:11,304 basehttp 124 "POST /admin/ HTTP/1.1" 403 2508
WARNING 2021-04-13 19:12:48,222 base 93 Not Found: /
WARNING 2021-04-13 19:12:48,224 basehttp 124 "GET / HTTP/1.1" 404 2151
WARNING 2021-04-13 19:12:48,711 base 93 Not Found: /favicon.ico
WARNING 2021-04-13 19:12:48,712 basehttp 124 "GET /favicon.ico HTTP/1.1" 404 2202
WARNING 2021-04-14 00:49:54,412 base 93 Not Found: /user/login/
WARNING 2021-04-14 00:49:54,413 basehttp 124 "POST /user/login/ HTTP/1.1" 404 2203
WARNING 2021-04-14 00:50:07,275 base 93 Not Found: /
WARNING 2021-04-14 00:50:07,276 basehttp 124 "GET / HTTP/1.1" 404 2151
WARNING 2021-04-14 00:51:44,431 base 93 Not Found: /user/login/
WARNING 2021-04-14 00:51:44,431 basehttp 124 "POST /user/login/ HTTP/1.1" 404 2203
WARNING 2021-04-14 00:51:53,215 base 93 Not Found: /user/login/
WARNING 2021-04-14 00:51:53,215 basehttp 124 "POST /user/login/ HTTP/1.1" 404 2203
WARNING 2021-04-14 00:52:54,182 base 93 Not Found: /user/login/
WARNING 2021-04-14 00:52:54,183 basehttp 124 "POST /user/login/ HTTP/1.1" 404 2203
WARNING 2021-04-14 01:07:59,270 base 93 Not Found: /user/login/
WARNING 2021-04-14 01:07:59,270 basehttp 124 "POST /user/login/ HTTP/1.1" 404 2203
WARNING 2021-04-14 01:10:00,531 basehttp 124 "POST /user/login/ HTTP/1.1" 400 67
WARNING 2021-04-14 01:10:03,534 basehttp 124 "POST /user/login/ HTTP/1.1" 400 67
WARNING 2021-04-14 01:44:22,317 basehttp 124 "POST /user/login/ HTTP/1.1" 400 67
WARNING 2021-04-14 01:45:04,528 basehttp 124 "POST /user/login/ HTTP/1.1" 400 67
WARNING 2021-04-14 01:54:09,526 basehttp 124 "POST /user/login/ HTTP/1.1" 400 67
WARNING 2021-04-14 02:27:12,603 base 93 Not Found: /
WARNING 2021-04-14 02:27:12,604 basehttp 124 "GET / HTTP/1.1" 404 2256
WARNING 2021-04-14 02:27:13,067 base 93 Not Found: /favicon.ico
WARNING 2021-04-14 02:27:13,068 basehttp 124 "GET /favicon.ico HTTP/1.1" 404 2307
WARNING 2021-04-14 02:27:22,304 basehttp 124 "GET /user/captcha/ HTTP/1.1" 400 11767
WARNING 2021-04-14 02:28:25,674 basehttp 124 "GET /user/captcha/?username=hry HTTP/1.1" 400 11853
WARNING 2021-04-14 02:35:04,288 basehttp 124 "GET /user/captcha/?account=hry HTTP/1.1" 400 11847
ERROR 2021-04-14 17:34:06,886 basehttp 124 "GET /home/footer/ HTTP/1.1" 500 59
ERROR 2021-04-14 17:34:06,887 basehttp 124 "GET /home/banner/ HTTP/1.1" 500 59
ERROR 2021-04-14 17:34:06,887 basehttp 124 "GET /home/header/ HTTP/1.1" 500 59
WARNING 2021-04-14 17:44:49,704 basehttp 124 "POST /user/register/ HTTP/1.1" 400 115
